"""Integration tests for error handling and recovery.

These tests verify the server behaves gracefully during failures.
They must fail initially (RED phase) before implementation.
"""

from unittest.mock import AsyncMock, patch

import pytest

from src.services.connection_manager import ConnectionManager
from src.services.joplin_client import JoplinClient


class TestErrorHandlingIntegration:
    """Test error handling and recovery integration scenarios."""

    @pytest.mark.asyncio
    async def test_joplin_server_shutdown_recovery(self) -> None:
        """Test server detects Joplin shutdown and recovers when restarted."""
        # This will fail until connection recovery is implemented
        config = {
            "base_url": "http://localhost:41184",
            "api_token": "test-token-123",
            "max_retries": 3,
            "retry_delay": 0.1
        }

        manager = ConnectionManager(config)

        # Simulate connection states: connected -> failed -> recovered
        connection_states = [True, False, False, True]  # Retry twice, then succeed
        state_index = 0

        async def mock_ping():
            nonlocal state_index
            result = connection_states[state_index]
            state_index += 1
            return result

        with patch.object(manager.client, 'ping', side_effect=mock_ping):
            # Should detect failure and recover
            is_recovered = await manager.ensure_connected()
            assert is_recovered is True
            assert state_index == 4  # All states checked

    @pytest.mark.asyncio
    async def test_authentication_token_expiry_handling(self) -> None:
        """Test handling of expired authentication tokens."""
        # This will fail until token expiry detection is implemented
        config = {
            "base_url": "http://localhost:41184",
            "api_token": "expired-token-123"
        }

        client = JoplinClient(config)

        # Mock 401 Unauthorized response
        with patch('httpx.AsyncClient.get') as mock_get:
            mock_response = AsyncMock()
            mock_response.status_code = 401
            mock_response.text = "Invalid token"
            mock_get.return_value = mock_response

            with pytest.raises(Exception) as exc_info:
                await client.search_notes("test query")

            # Should raise authentication error with helpful message
            error_msg = str(exc_info.value).lower()
            assert any(word in error_msg for word in ["auth", "token", "unauthorized", "invalid"])

    @pytest.mark.asyncio
    async def test_network_interruption_recovery(self) -> None:
        """Test recovery from temporary network interruptions."""
        # This will fail until network error recovery is implemented
        config = {
            "base_url": "http://localhost:41184",
            "api_token": "test-token-123",
            "max_retries": 2,
            "retry_delay": 0.1
        }

        client = JoplinClient(config)

        # Mock network failure then success
        call_count = 0
        def mock_request(*args, **kwargs):
            nonlocal call_count
            call_count += 1
            if call_count == 1:
                import httpx
                raise httpx.ConnectError("Network unreachable")
            else:
                # Success response
                response = AsyncMock()
                response.status_code = 200
                response.json.return_value = {"items": []}
                return response

        with patch('httpx.AsyncClient.get', side_effect=mock_request):
            # Should retry and succeed
            result = await client.search_notes("test")
            assert result == {"items": []}
            assert call_count == 2  # First failed, second succeeded

    @pytest.mark.asyncio
    async def test_malformed_json_response_handling(self) -> None:
        """Test handling of malformed JSON responses from Joplin."""
        # This will fail until JSON parsing error handling is implemented
        config = {
            "base_url": "http://localhost:41184",
            "api_token": "test-token-123"
        }

        client = JoplinClient(config)

        malformed_responses = [
            "invalid json{",  # Malformed JSON
            "",  # Empty response
            "<html>Error Page</html>",  # HTML instead of JSON
            '{"incomplete": json',  # Incomplete JSON
        ]

        for malformed_json in malformed_responses:
            with patch('httpx.AsyncClient.get') as mock_get:
                mock_response = AsyncMock()
                mock_response.status_code = 200
                mock_response.text = malformed_json
                mock_response.json.side_effect = Exception("JSON decode error")
                mock_get.return_value = mock_response

                with pytest.raises(Exception) as exc_info:
                    await client.search_notes("test")

                # Should raise meaningful error about JSON parsing
                error_msg = str(exc_info.value).lower()
                assert any(word in error_msg for word in ["json", "parse", "invalid", "decode"])

    @pytest.mark.asyncio
    async def test_rate_limit_handling(self) -> None:
        """Test proper handling of rate limit responses."""
        # This will fail until rate limit handling is implemented
        config = {
            "base_url": "http://localhost:41184",
            "api_token": "test-token-123"
        }

        client = JoplinClient(config)

        # Mock 429 Too Many Requests response
        with patch('httpx.AsyncClient.get') as mock_get:
            mock_response = AsyncMock()
            mock_response.status_code = 429
            mock_response.headers = {"Retry-After": "60"}
            mock_response.text = "Too Many Requests"
            mock_get.return_value = mock_response

            with pytest.raises(Exception) as exc_info:
                await client.search_notes("test")

            # Should raise rate limit error with retry information
            error_msg = str(exc_info.value).lower()
            assert any(word in error_msg for word in ["rate", "limit", "429", "retry"])

    @pytest.mark.asyncio
    async def test_large_response_handling(self) -> None:
        """Test handling of very large API responses without memory issues."""
        # This will fail until streaming/chunked response handling is implemented
        config = {
            "base_url": "http://localhost:41184",
            "api_token": "test-token-123"
        }

        client = JoplinClient(config)

        # Create mock response with large dataset
        large_notes = []
        for i in range(1000):  # 1000 notes
            large_notes.append({
                "id": f"note{i:04d}",
                "title": f"Note {i}",
                "body": "Content " * 1000,  # Large body content
                "parent_id": "notebook1",
                "created_time": 1704067200000 + i,
                "updated_time": 1704067200000 + i
            })

        large_response = {"items": large_notes}

        with patch.object(client, 'search_notes') as mock_search:
            mock_search.return_value = large_response

            # Should handle large response without memory/timeout issues
            result = await client.search_notes("test")

            assert len(result["items"]) == 1000
            # Should not consume excessive memory
            import sys
            assert sys.getsizeof(result) < 100 * 1024 * 1024  # Less than 100MB

    @pytest.mark.asyncio
    async def test_concurrent_request_error_isolation(self) -> None:
        """Test that errors in one request don't affect others."""
        # This will fail until proper error isolation is implemented
        config = {
            "base_url": "http://localhost:41184",
            "api_token": "test-token-123"
        }

        client = JoplinClient(config)

        # Mock: first request fails, second succeeds
        request_count = 0
        def mock_request(*args, **kwargs):
            nonlocal request_count
            request_count += 1

            if request_count == 1:
                import httpx
                raise httpx.ConnectError("Connection failed")
            else:
                response = AsyncMock()
                response.status_code = 200
                response.json.return_value = {"items": [{"id": "note1", "title": "Test"}]}
                return response

        with patch('httpx.AsyncClient.get', side_effect=mock_request):
            # Run concurrent requests
            import asyncio

            async def failing_request():
                try:
                    await client.search_notes("query1")
                    return "success"
                except:
                    return "failed"

            async def successful_request():
                try:
                    result = await client.search_notes("query2")
                    return "success" if result else "failed"
                except:
                    return "failed"

            # Both requests run concurrently
            results = await asyncio.gather(
                failing_request(),
                successful_request(),
                return_exceptions=True
            )

            # One should fail, one should succeed
            assert "failed" in results
            assert "success" in results

    @pytest.mark.asyncio
    async def test_graceful_degradation_during_partial_failures(self) -> None:
        """Test system continues operating during partial failures."""
        # This will fail until graceful degradation is implemented
        config = {
            "base_url": "http://localhost:41184",
            "api_token": "test-token-123"
        }

        client = JoplinClient(config)

        # Mock: search works, but individual note retrieval fails
        def mock_request(method, url, *args, **kwargs):
            if "search" in url:
                # Search succeeds
                response = AsyncMock()
                response.status_code = 200
                response.json.return_value = {
                    "items": [
                        {"id": "note1", "title": "Available Note"},
                        {"id": "note2", "title": "Unavailable Note"}
                    ]
                }
                return response
            elif "note2" in url:
                # Specific note fails
                response = AsyncMock()
                response.status_code = 500
                response.text = "Internal Server Error"
                return response
            else:
                # Other notes succeed
                response = AsyncMock()
                response.status_code = 200
                response.json.return_value = {
                    "id": "note1",
                    "title": "Available Note",
                    "body": "Content available"
                }
                return response

        with patch('httpx.AsyncClient.request', side_effect=mock_request):
            # Search should work
            search_result = await client.search_notes("test")
            assert len(search_result["items"]) == 2

            # First note should work
            note1 = await client.get_note("note1")
            assert note1["title"] == "Available Note"

            # Second note should fail gracefully
            with pytest.raises(Exception):
                await client.get_note("note2")

    @pytest.mark.asyncio
    async def test_structured_error_logging(self) -> None:
        """Test that errors are logged with structured context."""
        # This will fail until structured logging is implemented
        config = {
            "base_url": "http://localhost:41184",
            "api_token": "test-token-123"
        }

        client = JoplinClient(config)

        with patch('httpx.AsyncClient.get') as mock_get:
            import httpx
            mock_get.side_effect = httpx.ConnectError("Connection refused")

            # Mock logger to capture log calls
            with patch('src.services.joplin_client.logger') as mock_logger:
                try:
                    await client.search_notes("test query")
                except:
                    pass  # Expected to fail

                # Should log error with structured context
                assert mock_logger.error.called

                # Check log call contains context
                log_calls = mock_logger.error.call_args_list
                assert len(log_calls) > 0

                # Log should contain operation context
                logged_args = str(log_calls[0])
                assert any(word in logged_args.lower() for word in ["search", "connection", "error"])
